## **Chapter 8: Exception Handling in Asynchronous Code**

### **8.1. Introduction to Exception Handling in Asynchronous Programming**

In asynchronous programming, exception handling plays a crucial role in ensuring the reliability and resilience of applications. Since asynchronous code often executes concurrently and interacts with external resources such as networks or files, the likelihood of errors increases. Proper exception handling helps prevent application crashes, manage errors gracefully, and ensure the correct termination of tasks.

### **8.2. Basics of Exception Handling in Asynchronous Code**

In Python, exception handling is performed using the `try-except` construct. In asynchronous code, this construct is applied similarly to synchronous code but with some nuances related to asynchrony.

#### **8.2.1. Basic `try-except` Structure**

```python
import asyncio

async def faulty_task():
    try:
        print("Task execution started")
        await asyncio.sleep(1)
        raise ValueError("An error occurred in the task")
    except ValueError as e:
        print(f"Exception caught: {e}")
    finally:
        print("Task completion")

async def main():
    await faulty_task()

if __name__ == "__main__":
    asyncio.run(main())
```

**Output:**
```
Task execution started
Exception caught: An error occurred in the task
Task completion
```

In this example, the asynchronous function `faulty_task` raises a `ValueError`, which is caught by the `except` block. The `finally` block executes regardless of whether an exception occurred, ensuring that the task completes properly.

#### **8.2.2. Handling Multiple Exception Types**

You can handle different types of exceptions by adding additional `except` blocks.

```python
import asyncio

async def multiple_exceptions():
    try:
        await asyncio.sleep(1)
        # Raising different exceptions
        raise ValueError("Invalid value")
    except ValueError as ve:
        print(f"Handled ValueError: {ve}")
    except TypeError as te:
        print(f"Handled TypeError: {te}")
    except Exception as e:
        print(f"Handled general exception: {e}")
    finally:
        print("Exception handling completed")

async def main():
    await multiple_exceptions()

if __name__ == "__main__":
    asyncio.run(main())
```

**Output:**
```
Handled ValueError: Invalid value
Exception handling completed
```

In this example, the function `multiple_exceptions` can handle various types of exceptions, providing more detailed error management.

### **8.3. Exceptions in `asyncio.gather`**

The `asyncio.gather` function is used to execute multiple coroutines concurrently. By default, if one of the coroutines raises an error, `asyncio.gather` will raise an exception, and the execution of other coroutines will be canceled. However, you can alter this behavior using the `return_exceptions` parameter.

#### **8.3.1. Default Behavior**

```python
import asyncio

async def task_success():
    await asyncio.sleep(1)
    print("Task completed successfully")
    return "Success"

async def task_failure():
    await asyncio.sleep(2)
    raise RuntimeError("Task error")

async def main():
    try:
        results = await asyncio.gather(task_success(), task_failure())
    except RuntimeError as e:
        print(f"Exception from gather: {e}")

if __name__ == "__main__":
    asyncio.run(main())
```

**Output:**
```
Task completed successfully
Exception from gather: Task error
```

In this example, despite the first task completing successfully, the error in the second task causes `asyncio.gather` to raise a `RuntimeError`.

#### **8.3.2. Handling Exceptions with `return_exceptions=True`**

If you set `return_exceptions=True`, `asyncio.gather` will return all results, including exceptions, instead of raising the first encountered exception.

```python
import asyncio

async def task_success():
    await asyncio.sleep(1)
    print("Task completed successfully")
    return "Success"

async def task_failure():
    await asyncio.sleep(2)
    raise RuntimeError("Task error")

async def main():
    results = await asyncio.gather(task_success(), task_failure(), return_exceptions=True)
    for result in results:
        if isinstance(result, Exception):
            print(f"Exception received: {result}")
        else:
            print(f"Result: {result}")

if __name__ == "__main__":
    asyncio.run(main())
```

**Output:**
```
Task completed successfully
Exception received: Task error
Result: Success
```

In this example, both tasks complete independently, and all results (including exceptions) are available for further processing.

### **8.4. Exceptions in Background Tasks**

Background tasks (`asyncio.create_task`) can terminate with errors that are not always explicitly handled. If an exception in a background task is not handled, it can lead to warnings and potential resource leaks.

#### **8.4.1. Example of an Unhandled Exception in a Background Task**

```python
import asyncio

async def faulty_task():
    await asyncio.sleep(1)
    raise ValueError("Error in background task")

async def main():
    task = asyncio.create_task(faulty_task())
    await asyncio.sleep(2)

if __name__ == "__main__":
    asyncio.run(main())
```

**Output:**
```
Exception in callback _ProactorBasePipeTransport._loop_callback()
handle: <Handle _ProactorBasePipeTransport._loop_callback()>
Traceback (most recent call last):
  File "C:\Python39\lib\asyncio\base_events.py", line 1822, in _run
    self._context.run(self._callback, *self._args)
  File "C:\Python39\lib\asyncio\windows_events.py", line 142, in _loop_callback
    self._callback(*self._args)
  File "C:\Python39\lib\asyncio\windows_events.py", line 255, in _add_writer
    self._add_to_selector(fd, selectors.EVENT_WRITE, callback)
  File "C:\Python39\lib\asyncio\base_events.py", line 618, in _add_to_selector
    self._selector.register(fileobj, events, data)
  File "C:\Python39\lib\selectors.py", line 507, in register
    key = self._selector.register(fileobj, events, data)
ValueError: unsupported operation on closed file.
```

This warning indicates that the exception in the background task was not handled.

#### **8.4.2. Properly Handling Exceptions in Background Tasks**

To avoid such issues, you must explicitly handle exceptions in background tasks.

**Example:**

```python
import asyncio

async def faulty_task():
    try:
        await asyncio.sleep(1)
        raise ValueError("Error in background task")
    except ValueError as e:
        print(f"Exception in background task handled: {e}")

async def main():
    task = asyncio.create_task(faulty_task())
    await asyncio.sleep(2)

if __name__ == "__main__":
    asyncio.run(main())
```

**Output:**
```
Exception in background task handled: Error in background task
```

In this example, the exception within the background task is handled inside the task itself, preventing unhandled exceptions.

### **8.5. Using `asyncio.shield` to Protect Coroutines from Cancellation and Errors**

`asyncio.shield` allows you to protect a coroutine from being canceled or affected by errors, ensuring its execution continues independently of external conditions.

#### **8.5.1. Example of Using `asyncio.shield`**

```python
import asyncio

async def critical_task():
    try:
        print("Critical task started")
        await asyncio.sleep(3)
        print("Critical task completed")
    except asyncio.CancelledError:
        print("Critical task was canceled")

async def main():
    task = asyncio.create_task(asyncio.shield(critical_task()))
    await asyncio.sleep(1)
    task.cancel()
    try:
        await task
    except asyncio.CancelledError:
        print("Task was canceled, but shield protected the critical task")

if __name__ == "__main__":
    asyncio.run(main())
```

**Output:**
```
Critical task started
Task was canceled, but shield protected the critical task
Critical task completed
```

In this example, using `asyncio.shield` prevents the cancellation of `critical_task` even when the main task is canceled.

#### **8.5.2. Applying `asyncio.shield` to Manage Task Lifecycles**

`asyncio.shield` is useful when you want to ensure certain coroutines execute to completion, even if the main event loop encounters errors or cancels tasks.

### **8.6. Context Managers for Exception Handling**

Context managers allow you to manage resources and ensure their proper release even in the event of exceptions.

#### **8.6.1. Using `async with` for Exception Handling**

```python
import asyncio

class AsyncResource:
    async def __aenter__(self):
        print("Resource opened")
        return self

    async def __aexit__(self, exc_type, exc, tb):
        if exc:
            print(f"Exception: {exc}")
        print("Resource closed")
        return False  # Propagate exception

async def main():
    try:
        async with AsyncResource() as resource:
            print("Using the resource")
            raise RuntimeError("Error while using the resource")
    except RuntimeError as e:
        print(f"Exception caught in main: {e}")

if __name__ == "__main__":
    asyncio.run(main())
```

**Output:**
```
Resource opened
Using the resource
Exception: Error while using the resource
Resource closed
Exception caught in main: Error while using the resource
```

In this example, the context manager `AsyncResource` ensures the resource is properly closed even when an exception occurs within the `async with` block.

### **8.7. Logging Exceptions**

Using the `logging` module to record exceptions is a good practice, especially in large and complex applications.

#### **8.7.1. Setting Up Logging**

```python
import asyncio
import logging

# Setting up logging
logging.basicConfig(level=logging.INFO)
logger = logging.getLogger(__name__)

async def faulty_task():
    await asyncio.sleep(1)
    raise ValueError("An error occurred in the task")

async def main():
    try:
        await faulty_task()
    except ValueError as e:
        logger.error(f"Exception caught in main: {e}")

if __name__ == "__main__":
    asyncio.run(main())
```

**Output:**
```
ERROR:__main__:Exception caught in main: An error occurred in the task
```

In this example, the exception is logged with the `ERROR` level, allowing you to track errors within the application.

#### **8.7.2. Logging Exceptions in Background Tasks**

```python
import asyncio
import logging

logging.basicConfig(level=logging.INFO)
logger = logging.getLogger(__name__)

async def faulty_task():
    await asyncio.sleep(1)
    raise ValueError("Error in background task")

async def main():
    task = asyncio.create_task(faulty_task())

    try:
        await task
    except Exception as e:
        logger.exception("Exception in background task")

if __name__ == "__main__":
    asyncio.run(main())
```

**Output:**
```
ERROR:__main__:Exception in background task
Traceback (most recent call last):
  File "async_exception.py", line 9, in faulty_task
    raise ValueError("Error in background task")
ValueError: Error in background task
```

Using `logger.exception` automatically includes the stack trace, which aids in debugging.

### **8.8. Practical Examples of Exception Handling**

#### **8.8.1. Asynchronous HTTP Client with Error Handling**

```python
import asyncio
import aiohttp
import logging

logging.basicConfig(level=logging.INFO)
logger = logging.getLogger(__name__)

async def fetch(session, url):
    try:
        async with session.get(url, timeout=5) as response:
            response.raise_for_status()
            data = await response.text()
            logger.info(f"Downloaded {url} with {len(data)} characters")
            return data
    except aiohttp.ClientError as e:
        logger.error(f"Error requesting {url}: {e}")
    except asyncio.TimeoutError:
        logger.error(f"Timeout requesting {url}")

async def main():
    urls = [
        'https://www.example.com',
        'https://www.nonexistenturl.com',
        'https://httpbin.org/delay/6',  # Timeout
    ]
    async with aiohttp.ClientSession() as session:
        tasks = [fetch(session, url) for url in urls]
        results = await asyncio.gather(*tasks, return_exceptions=True)
        for result in results:
            if isinstance(result, Exception):
                logger.error(f"Exception received: {result}")
            elif result:
                logger.info(f"Result: {result[:100]}...")

if __name__ == "__main__":
    asyncio.run(main())
```

**Output:**
```
INFO:__main__:Downloaded https://www.example.com with 1256 characters
ERROR:__main__:Error requesting https://www.nonexistenturl.com: Cannot connect to host www.nonexistenturl.com:443 ssl:default [Name or service not known]
ERROR:__main__:Timeout requesting https://httpbin.org/delay/6
ERROR:__main__:Exception received: Cannot connect to host www.nonexistenturl.com:443 ssl:default [Name or service not known]
ERROR:__main__:Exception received: Timeout requesting https://httpbin.org/delay/6
INFO:__main__:Result: <HTML>...
```

In this example, an asynchronous HTTP client performs requests to multiple URLs, handling various types of errors such as unavailable hosts and timeouts.

#### **8.8.2. Asynchronous Web Server with Error Handling**

```python
from aiohttp import web
import asyncio
import logging

logging.basicConfig(level=logging.INFO)
logger = logging.getLogger(__name__)

async def handle(request):
    try:
        data = await request.json()
        if 'value' not in data:
            raise web.HTTPBadRequest(text="Missing 'value' field")
        result = int(data['value']) * 2
        return web.json_response({"result": result})
    except web.HTTPException as e:
        raise e
    except Exception as e:
        logger.exception("Unhandled exception")
        raise web.HTTPInternalServerError(text="Internal server error")

app = web.Application()
app.add_routes([web.post('/multiply', handle)])

if __name__ == '__main__':
    web.run_app(app, host='127.0.0.1', port=8080)
```

**Description:**

- The server listens for POST requests at the `/multiply` route.
- It expects JSON data with a `value` field.
- If the `value` field is missing, it returns a `400 Bad Request` error.
- If any other error occurs, it logs the exception and returns a `500 Internal Server Error`.

**Example Requests Using `curl`:**

```bash
curl -X POST -H "Content-Type: application/json" -d '{"value": 10}' http://127.0.0.1:8080/multiply
```

**Response:**
```json
{
  "result": 20
}
```

**Example Request Missing the `value` Field:**

```bash
curl -X POST -H "Content-Type: application/json" -d '{"number": 10}' http://127.0.0.1:8080/multiply
```

**Response:**
```
Missing 'value' field
```

### **8.9. Tips and Recommendations for Exception Handling**

#### **8.9.1. Handle Specific Exceptions Before General Ones**

Always handle more specific exceptions before general ones. This allows for more precise error management and provides more detailed messages.

```python
try:
    # Code that may raise exceptions
    pass
except ValueError:
    # Handle ValueError
    pass
except Exception:
    # Handle all other exceptions
    pass
```

#### **8.9.2. Use `finally` for Resource Cleanup**

The `finally` block ensures that code runs regardless of whether an exception occurred, which is useful for releasing resources.

```python
async def process():
    try:
        resource = await acquire_resource()
        # Work with the resource
    except Exception as e:
        logger.error(f"Error: {e}")
    finally:
        await release_resource(resource)
```

#### **8.9.3. Do Not Suppress Exceptions Unnecessarily**

Avoid using empty `except` blocks that suppress all exceptions without handling them. This can make debugging difficult and lead to hidden errors.

```python
# Bad:
try:
    # Code
    pass
except:
    pass

# Good:
try:
    # Code
    pass
except SpecificException as e:
    # Handle specific exception
    pass
```

#### **8.9.4. Log Exceptions for Debugging**

Use the `logging` module to record exceptions, which makes tracking and debugging easier.

```python
import logging

logger = logging.getLogger(__name__)

try:
    # Code that may raise an exception
    pass
except Exception as e:
    logger.exception("An error occurred")
```

### **8.10. Conclusion**

Exception handling in asynchronous programming with Python requires careful consideration to ensure the reliability and resilience of applications. Proper use of `try-except` constructs, managing exceptions in background tasks, utilizing `asyncio.shield` to protect critical coroutines, and applying context managers allow for effective error management and prevent application crashes.